<?xml version="1.0"?>
<robot xmlns:xacro="http://ros.org/wiki/xacro">
  <xacro:property name="base_radius" value="0.150"/>
  <xacro:property name="base_height" value="0.068"/>



  <xacro:property name="wheel_radius" value="0.0215"/>
  <xacro:property name="wheel_width" value="0.018"/>

  <xacro:property name="wheel_dy" value="0.107954"/>
  <xacro:property name="wheel_dx" value="-0.033046"/>
  <xacro:property name="wheel_dz" value="-0.026"/>

  <xacro:property name="caster_dx" value="0.120"/>
  <xacro:property name="caster_dz" value="-0.0350625"/>
  <xacro:property name="caster_radius" value="0.0079375"/>




  <link name="base_link">
    <visual>
      <geometry>
        <cylinder radius="${base_radius}" length="${base_height}"/>
      </geometry>
      <material name="Cyan">
        <color rgba="0 1.0 1.0 0.5"/>
      </material>
    </visual>
  </link>


  <link name="base_footprint"/>

  <joint name="base_joint" type="fixed">
    <parent link="base_link"/>
    <child link="base_footprint"/>
    <origin xyz="0.0 0.0 ${0.11}" rpy="0 0 0"/>
  </joint>


  <link name="left_wheel_link">
    <visual>
      <origin xyz="0 0 0" rpy="${pi/2} 0 0"/>
      <geometry>
        <cylinder radius="${wheel_radius}" length="${wheel_width}"/>
      </geometry>
      <material name="Gray">
        <color rgba="0.5 0.5 0.5 1.0"/>
      </material>
    </visual>
  </link>

  <link name="right_wheel_link">
    <visual>
      <origin xyz="0 0 0" rpy="${pi/2} 0 0"/>
      <geometry>
        <cylinder radius="${wheel_radius}" length="${wheel_width}"/>
      </geometry>
      <material name="Gray">
        <color rgba="0.5 0.5 0.5 1.0"/>
      </material>
    </visual>
  </link>



  <joint name="left_wheel_joint" type="continuous">
    <parent link="base_link"/>
    <child link="left_wheel_link"/>
    <origin xyz="${wheel_dx} ${wheel_dy} ${wheel_dz}" rpy="0 0 0"/>
  </joint>


  <joint name="right_wheel_joint" type="continuous">
    <parent link="base_link"/>
    <child link="right_wheel_link"/>
    <origin xyz="${wheel_dx} ${-wheel_dy} ${wheel_dz}" rpy="0 0 0"/>
  </joint>

  <link name="front_caster">
    <visual>
      <geometry>
        <sphere radius="${caster_radius}"/>
      </geometry>
      <material name="Cyan">
        <color rgba="0 1.0 1.0 1.0"/>
      </material>
    </visual>
  </link>


  <joint name="caster_joint" type="fixed">
    <parent link="base_link"/>
    <child link="front_caster"/>
    <origin xyz="${caster_dx} 0.0 ${caster_dz}" rpy="0 0 0"/>
  </joint>

</robot>