<?xml version="1.0"?>
<robot xmlns:xacro="http://ros.org/wiki/xacro">

    <xacro:property name="base_radius" value="0.150"/>
    <xacro:property name="base_height" value="0.068"/>

    <xacro:property name="wheel_radius" value="0.0215"/>
    <xacro:property name="wheel_width" value="0.018"/>

    <xacro:property name="wheel_dy" value="0.107954"/>
    <xacro:property name="wheel_dx" value="-0.033046"/>
    <xacro:property name="wheel_dz" value="-0.026"/>

    <xacro:property name="caster_dx" value="0.120"/>
    <xacro:property name="caster_dz" value="-0.0350625"/>
    <xacro:property name="caster_radius" value="0.0079375"/>

    <xacro:macro name="box_inertia" params="m w h d">
        <inertial>
            <origin xyz="0 0 0" rpy="${pi/2} 0 ${pi/2}"/>
            <mass value="${m}"/>
            <inertia ixx="${(m/12) * (h*h + d*d)}" ixy="0.0" ixz="0.0" iyy="${(m/12) * (w*w + d*d)}" iyz="0.0" izz="${(m/12) * (w*w + h*h)}"/>
        </inertial>
    </xacro:macro>

    <xacro:macro name="cylinder_inertia" params="m r h">
        <inertial>
            <origin xyz="0 0 0" rpy="${pi/2} 0 0" />
            <mass value="${m}"/>
            <inertia ixx="${(m/12) * (3*r*r + h*h)}" ixy = "0" ixz = "0" iyy="${(m/12) * (3*r*r + h*h)}" iyz = "0" izz="${(m/2) * (r*r)}"/>
        </inertial>
    </xacro:macro>

    <xacro:macro name="sphere_inertia" params="m r">
        <inertial>
            <mass value="${m}"/>
            <inertia ixx="${(2/5) * m * (r*r)}" ixy="0.0" ixz="0.0" iyy="${(2/5) * m * (r*r)}" iyz="0.0" izz="${(2/5) * m * (r*r)}"/>
        </inertial>
    </xacro:macro>





    <link name="base_link">
        <visual>
            <geometry>
                <cylinder radius="${base_radius}" length="${base_height}"/>
            </geometry>
            <material name="Cyan">
                <color rgba="0 1.0 1.0 0.5"/>
            </material>
        </visual>
        <collision>
            <origin xyz="0 0 0" rpy="${pi/2} 0 0"/>
            <geometry>
                <box size="${base_radius*2.0} ${base_height} ${base_radius*2.0}"/>
                <cylinder radius="${base_radius}" length="${base_height}"/>
            </geometry>
        </collision>
        <xacro:box_inertia m="1" w="${base_radius*2}" d="${base_radius*2}" h="${base_height}"/>
    </link>

    <link name="base_footprint"/>

    <joint name="base_joint" type="fixed">
        <parent link="base_link"/>
        <child link="base_footprint"/>
        <origin xyz="0.0 0.0 ${0.11}" rpy="0 0 0"/>
    </joint>


    <link name="left_wheel_link">
        <visual>
            <origin xyz="0 0 0" rpy="${pi/2} 0 0"/>
            <geometry>
                <cylinder radius="${wheel_radius}" length="${wheel_width}"/>
            </geometry>
            <material name="Gray">
                <color rgba="0.5 0.5 0.5 1.0"/>
            </material>
        </visual>
        <collision>
            <origin xyz="0 0 0" rpy="${pi/2} 0 0"/>
            <geometry>
                <cylinder radius="${wheel_radius}" length="${wheel_width}"/>
            </geometry>
        </collision>
        <xacro:cylinder_inertia m="0.01" r="${wheel_radius}" h="${wheel_width}"/>
    </link>

    <link name="right_wheel_link">
            <visual>
            <origin xyz="0 0 0" rpy="${pi/2} 0 0"/>
            <geometry>
                <cylinder radius="${wheel_radius}" length="${wheel_width}"/>
            </geometry>
            <material name="Gray">
                <color rgba="0.5 0.5 0.5 1.0"/>
            </material>
        </visual>
        <collision>
            <origin xyz="0 0 0" rpy="${pi/2} 0 0"/>
            <geometry>
                <cylinder radius="${wheel_radius}" length="${wheel_width}"/>
            </geometry>
        </collision>
        <xacro:cylinder_inertia m="0.01" r="${wheel_radius}" h="${wheel_width}"/>
    </link>

    <joint name="left_wheel_joint" type="continuous">
        <parent link="base_link"/>
        <child link="left_wheel_link"/>
        <origin xyz="${wheel_dx} ${wheel_dy} ${wheel_dz}" rpy="0 0 0"/>
    </joint>


    <joint name="right_wheel_joint" type="continuous">
        <parent link="base_link"/>
        <child link="right_wheel_link"/>
        <origin xyz="${wheel_dx} ${-wheel_dy} ${wheel_dz}" rpy="0 0 0"/>
    </joint>

    <link name="front_caster">
        <visual>
            <geometry>
                <sphere radius="${caster_radius}"/>
            </geometry>
            <material name="Cyan">
                <color rgba="0 1.0 1.0 1.0"/>
            </material>
        </visual>
        <collision>
            <origin xyz="0 0 0" rpy="0 0 0"/>
            <geometry>
                <sphere radius="${caster_radius}"/>
            </geometry>
        </collision>
        <xacro:sphere_inertia m="0.005" r="${caster_radius}"/>
    </link>


    <joint name="caster_joint" type="fixed">
        <parent link="base_link"/>
        <child link="front_caster"/>
        <origin xyz="${caster_dx} 0.0 ${caster_dz}" rpy="0 0 0"/>
    </joint>

</robot>